certifi==2023.5.7
charset-normalizer==3.2.0
idna==3.4
Jinja2==3.1.2
MarkupSafe==2.1.3
numpy==1.25.1
pandas==2.0.3
pyasn1==0.5.0
pyTelegramBotAPI==4.12.0
python-dateutil==2.8.2
python-dotenv==1.0.0
pytz==2023.3
requests==2.31.0
rsa==4.9
six==1.16.0
telebot==0.0.5
tzdata==2023.3
urllib3==2.0.3






вывод ниже работа запроса в телеграмм коде 

C:\PYTHON\hh_bot\venv\Scripts\python.exe C:\PYTHON\hh_bot\main.py 
search params: {'text': 'программист', 'area': '1', 'salary': '70000', 'experience': 'noExperience', 'employment': 'full', 'schedule': 'remote', 'employer_id': None, 'page': 0, 'per_page': 100, 'period': 1}
count found vacancies: 4
Traceback (most recent call last):
  File "C:\PYTHON\hh_bot\venv\lib\site-packages\urllib3\connectionpool.py", line 536, in _make_request
    response = conn.getresponse()
  File "C:\PYTHON\hh_bot\venv\lib\site-packages\urllib3\connection.py", line 454, in getresponse
    httplib_response = super().getresponse()
  File "C:\Users\Ilya\AppData\Local\Programs\Python\Python310\lib\http\client.py", line 1374, in getresponse
    response.begin()
  File "C:\Users\Ilya\AppData\Local\Programs\Python\Python310\lib\http\client.py", line 318, in begin
    version, status, reason = self._read_status()
  File "C:\Users\Ilya\AppData\Local\Programs\Python\Python310\lib\http\client.py", line 279, in _read_status
    line = str(self.fp.readline(_MAXLINE + 1), "iso-8859-1")
  File "C:\Users\Ilya\AppData\Local\Programs\Python\Python310\lib\socket.py", line 705, in readinto
    return self._sock.recv_into(b)
  File "C:\Users\Ilya\AppData\Local\Programs\Python\Python310\lib\ssl.py", line 1274, in recv_into
    return self.read(nbytes, buffer)
  File "C:\Users\Ilya\AppData\Local\Programs\Python\Python310\lib\ssl.py", line 1130, in read
    return self._sslobj.read(len, buffer)
TimeoutError: The read operation timed out

The above exception was the direct cause of the following exception:

Traceback (most recent call last):
  File "C:\PYTHON\hh_bot\venv\lib\site-packages\requests\adapters.py", line 486, in send
    resp = conn.urlopen(
  File "C:\PYTHON\hh_bot\venv\lib\site-packages\urllib3\connectionpool.py", line 844, in urlopen
    retries = retries.increment(
  File "C:\PYTHON\hh_bot\venv\lib\site-packages\urllib3\util\retry.py", line 470, in increment
    raise reraise(type(error), error, _stacktrace)
  File "C:\PYTHON\hh_bot\venv\lib\site-packages\urllib3\util\util.py", line 39, in reraise
    raise value
  File "C:\PYTHON\hh_bot\venv\lib\site-packages\urllib3\connectionpool.py", line 790, in urlopen
    response = self._make_request(
  File "C:\PYTHON\hh_bot\venv\lib\site-packages\urllib3\connectionpool.py", line 538, in _make_request
    self._raise_timeout(err=e, url=url, timeout_value=read_timeout)
  File "C:\PYTHON\hh_bot\venv\lib\site-packages\urllib3\connectionpool.py", line 370, in _raise_timeout
    raise ReadTimeoutError(
urllib3.exceptions.ReadTimeoutError: HTTPSConnectionPool(host='api.telegram.org', port=443): Read timed out. (read timeout=25)

During handling of the above exception, another exception occurred:

Traceback (most recent call last):
  File "C:\PYTHON\hh_bot\main.py", line 6, in <module>
    telegram_bot(BOT_TOKEN)
  File "C:\PYTHON\hh_bot\bot.py", line 212, in telegram_bot
    bot.polling()
  File "C:\PYTHON\hh_bot\venv\lib\site-packages\telebot\__init__.py", line 1043, in polling
    self.__threaded_polling(non_stop=non_stop, interval=interval, timeout=timeout, long_polling_timeout=long_polling_timeout,
  File "C:\PYTHON\hh_bot\venv\lib\site-packages\telebot\__init__.py", line 1118, in __threaded_polling
    raise e
  File "C:\PYTHON\hh_bot\venv\lib\site-packages\telebot\__init__.py", line 1073, in __threaded_polling
    polling_thread.raise_exceptions()
  File "C:\PYTHON\hh_bot\venv\lib\site-packages\telebot\util.py", line 108, in raise_exceptions
    raise self.exception_info
  File "C:\PYTHON\hh_bot\venv\lib\site-packages\telebot\util.py", line 90, in run
    task(*args, **kwargs)
  File "C:\PYTHON\hh_bot\venv\lib\site-packages\telebot\__init__.py", line 649, in __retrieve_updates
    updates = self.get_updates(offset=(self.last_update_id + 1), 
  File "C:\PYTHON\hh_bot\venv\lib\site-packages\telebot\__init__.py", line 623, in get_updates
    json_updates = apihelper.get_updates(self.token, offset, limit, timeout, allowed_updates, long_polling_timeout)
  File "C:\PYTHON\hh_bot\venv\lib\site-packages\telebot\apihelper.py", line 321, in get_updates
    return _make_request(token, method_url, params=payload)
  File "C:\PYTHON\hh_bot\venv\lib\site-packages\telebot\apihelper.py", line 156, in _make_request
    result = _get_req_session().request(
  File "C:\PYTHON\hh_bot\venv\lib\site-packages\requests\sessions.py", line 589, in request
    resp = self.send(prep, **send_kwargs)
  File "C:\PYTHON\hh_bot\venv\lib\site-packages\requests\sessions.py", line 703, in send
    r = adapter.send(request, **kwargs)
  File "C:\PYTHON\hh_bot\venv\lib\site-packages\requests\adapters.py", line 532, in send
    raise ReadTimeout(e, request=request)
requests.exceptions.ReadTimeout: HTTPSConnectionPool(host='api.telegram.org', port=443): Read timed out. (read timeout=25)

Process finished with exit code 1







